<?xml version="1.0" ?>
<robot name="turtlebot3_waffle" xmlns:xacro="http://ros.org/wiki/xacro">
  <!-- <xacro:include filename="$(find turtlebot3_description)/urdf/common_properties.urdf"/>

  <xacro:property name="r200_cam_rgb_px" value="0.005"/>
  <xacro:property name="r200_cam_rgb_py" value="0.018"/>
  <xacro:property name="r200_cam_rgb_pz" value="0.013"/>
  <xacro:property name="r200_cam_depth_offset" value="0.01"/> -->

  <!-- Init colour -->
  <material name="black">
      <color rgba="0.0 0.0 0.0 1.0"/>
  </material>

  <material name="dark">
    <color rgba="0.3 0.3 0.3 1.0"/>
  </material>

  <material name="light_black">
    <color rgba="0.4 0.4 0.4 1.0"/>
  </material>

  <material name="blue">
    <color rgba="0.0 0.0 0.8 1.0"/>
  </material>

  <material name="green">
    <color rgba="0.0 0.8 0.0 1.0"/>
  </material>

  <material name="grey">
    <color rgba="0.5 0.5 0.5 1.0"/>
  </material>

  <material name="orange">
    <color rgba="1.0 0.4235 0.0392 1.0"/>
  </material>

  <material name="brown">
    <color rgba="0.8706 0.8118 0.7647 1.0"/>
  </material>

  <material name="red">
    <color rgba="0.8 0.0 0.0 1.0"/>
  </material>

  <material name="white">
    <color rgba="1.0 1.0 1.0 1.0"/>
  </material>

  <link name="base_footprint"/>

  <joint name="base_joint" type="fixed">
    <parent link="base_footprint"/>
    <child link="base_link" />
    <origin xyz="0 0 0.010" rpy="0 0 0"/>
  </joint>

  <link name="base_link">
    <visual>
      <origin xyz="-0.064 0 0.1" rpy="0 0 0"/>
      <geometry>
        <mesh filename="package://turtlebot3_gazebo/models/turtlebot3_common/meshes/waffle_base.dae"/>
      </geometry>
      <material name="light_black"/>
    </visual>

    <collision>
      <origin xyz="-0.064 0 0.1" rpy="0 0 0"/>
      <geometry>
        <box size="0.53 0.53 0.183"/>
      </geometry>
    </collision>

    <inertial>
      <origin xyz="-0.064 0 0.1" rpy="0 0 0"/>
      <mass value="1.3729096e+00"/>
      <inertia ixx="4.2111447e-02" ixy="0" ixz="0"
               iyy="4.2111447e-02" iyz="0"
               izz="7.5254874e-02" />
    </inertial>
  </link>

  <joint name="wheel_left_joint" type="continuous">
    <parent link="base_link"/>
    <child link="wheel_left_link"/>
    <origin xyz="0.0 0.144 0.023" rpy="-1.57 0 0"/>
    <axis xyz="0 0 1"/>
  </joint>

  <link name="wheel_left_link">
    <visual>
      <origin xyz="0 0.28 0.023" rpy="1.57 0 0"/>
      <geometry>
        <mesh filename="package://turtlebot3_gazebo/models/turtlebot3_common/meshes/tire.dae"/>
      </geometry>
      <material name="dark"/>
    </visual>

    <collision>
      <origin xyz="0 0.28 0.023" rpy="1.57 0 0"/>
      <geometry>
        <cylinder length="0.035" radius="0.066"/>
      </geometry>
    </collision>

    <inertial>
      <origin xyz="0 0.28 0.023" rpy="1.57 0 0"/>
      <mass value="0.2" />
      <inertia ixx="0.00023821666666666672" ixy="0" ixz="0"
               iyy="0.00023821666666666672" iyz="0"
               izz="0.00043560000000000007" />
      </inertial>
  </link>

  <joint name="wheel_right_joint" type="continuous">
    <parent link="base_link"/>
    <child link="wheel_right_link"/>
    <origin xyz="0.0 -0.144 0.023" rpy="-1.57 0 0"/>
    <axis xyz="0 0 1"/>
  </joint>

  <link name="wheel_right_link">
    <visual>
      <origin xyz="0.0 -0.28 0.023" rpy="1.57 0 0"/>
      <geometry>
        <mesh filename="package://turtlebot3_gazebo/models/turtlebot3_common/meshes/tire.dae"/>
      </geometry>
      <material name="dark"/>
    </visual>

    <collision>
      <origin xyz="0.0 -0.28 0.023" rpy="1.57 0 0"/>
      <geometry>
        <cylinder length="0.035" radius="0.066"/>
      </geometry>
    </collision>

    <inertial>
      <origin xyz="0.0 -0.28 0.023" rpy="1.57 0 0"/>
      <mass value="0.2" />
      <inertia ixx="0.00023821666666666672" ixy="0" ixz="0"
               iyy="0.00023821666666666672" iyz="0"
               izz="0.00043560000000000007" />
      </inertial>
  </link>

  <joint name="caster_back_right_joint" type="fixed">
    <parent link="base_link"/>
    <child link="caster_back_right_link"/>
  </joint>

  <link name="caster_back_right_link">
    <collision>
      <origin xyz="-0.25 -0.18 -0.004" rpy="-1.57 0 0"/>
      <geometry>
        <sphere radius="0.03"/>
      </geometry>
    </collision>

    <inertial>
      <origin xyz="-0.25 -0.18 -0.004" rpy="-1.57 0 0"/>
      <mass value="1.0" />
      <inertia ixx="0.00036" ixy="0.0" ixz="0.0"
               iyy="0.00036" iyz="0.0"
               izz="0.00036" />
    </inertial>
  </link>

  <joint name="caster_back_left_joint" type="fixed">
    <parent link="base_link"/>
    <child link="caster_back_left_link"/>
  </joint>

  <link name="caster_back_left_link">
    <collision>
      <origin xyz="-0.25 0.18 -0.004" rpy="-1.57 0 0"/>
      <geometry>
        <sphere radius="0.03"/>
      </geometry>
    </collision>

    <inertial>
      <origin xyz="-0.25 0.18 -0.004" rpy="-1.57 0 0"/>
      <mass value="1.0" />
      <inertia ixx="0.00036" ixy="0.0" ixz="0.0"
               iyy="0.00036" iyz="0.0"
               izz="0.00036" />
    </inertial>
  </link>

  <joint name="imu_joint" type="fixed">
    <parent link="base_link"/>
    <child link="imu_link"/>
    <origin xyz="-0.032 0 0.068" rpy="0 0 0"/>
  </joint>

  <link name="imu_link"/>

  <joint name="scan_joint" type="fixed">
    <parent link="base_link"/>
    <child link="base_scan"/>
    <origin xyz="-0.064 0 0.121" rpy="0 0 0"/>
  </joint>

  <link name="base_scan">
    <visual>
      <origin xyz="-0.052 0 0.211" rpy="0 0 0"/>
      <geometry>
        <mesh filename="package://turtlebot3_gazebo/models/turtlebot3_common/meshes/lds.dae" scale="0.001 0.001 0.001"/>
      </geometry>
      <material name="dark"/>
    </visual>

    <collision>
      <origin xyz="0.015 0 -0.0065" rpy="0 0 0"/>
      <geometry>
        <cylinder length="0.0315" radius="0.055"/>
      </geometry>
    </collision>

    <inertial>
      <mass value="0.114" />
      <origin xyz="-0.052 0 0.211" />
      <inertia ixx="0.001" ixy="0.0" ixz="0.0"
               iyy="0.001" iyz="0.0"
               izz="0.001" />
    </inertial>
  </link>

  <joint name="camera_joint" type="fixed">
    <origin xyz="0.064 -0.065 0.094" rpy="0 0 0"/>
    <parent link="base_link"/>
    <child link="camera_link"/>
  </joint>

  <link name="camera_link">
    <visual>
     <origin xyz="0 0 0" rpy="1.57 0 1.57"/>
      <geometry>
       <mesh filename="package://turtlebot3_gazebo/models/turtlebot3_common/meshes/r200.dae" />
      </geometry>
    </visual>
    <!--collision>
      <origin xyz="0.003 0.065 0.007" rpy="0 0 0"/>
      <geometry>
        <box size="0.012 0.132 0.020"/>
      </geometry>
    </collision-->

    <!-- This inertial field needs doesn't contain reliable data!! -->
<!--   <inertial>
      <mass value="0.564" />
      <origin xyz="0 0 0" />
      <inertia ixx="0.003881243" ixy="0.0" ixz="0.0"
               iyy="0.000498940" iyz="0.0"
               izz="0.003879257" />
    </inertial>-->
  </link>

  <joint name="camera_rgb_joint" type="fixed">
    <origin xyz="0.005 0.018 0.013" rpy="0 0 0"/>
    <!-- <origin xyz="${r200_cam_rgb_px} ${r200_cam_rgb_py} ${r200_cam_rgb_pz}" rpy="0 0 0"/> -->
    <parent link="camera_link"/>
    <child link="camera_rgb_frame"/>
  </joint>
  <link name="camera_rgb_frame"/>

  <joint name="camera_rgb_optical_joint" type="fixed">
    <origin xyz="0 0 0" rpy="-1.57 0 -1.57"/>
    <parent link="camera_rgb_frame"/>
    <child link="camera_rgb_optical_frame"/>
  </joint>
  <link name="camera_rgb_optical_frame"/>

  <joint name="camera_depth_joint" type="fixed">
    <origin xyz="0.005 0.028 0.013" rpy="0 0 0"/>
    <!-- <origin xyz="${r200_cam_rgb_px} ${r200_cam_rgb_py + r200_cam_depth_offset} ${r200_cam_rgb_pz}" rpy="0 0 0"/> -->
    <parent link="camera_link"/>
    <child link="camera_depth_frame"/>
  </joint>
  <link name="camera_depth_frame"/>

  <joint name="camera_depth_optical_joint" type="fixed">
    <origin xyz="0 0 0" rpy="-1.57 0 -1.57"/>
    <parent link="camera_depth_frame"/>
    <child link="camera_depth_optical_frame"/>
  </joint>
  <link name="camera_depth_optical_frame"/>

</robot>
