<?xml version="1.0" ?>
<sdf version="1.8">
  <model name="turtlebot3_waffle">  
  <pose>0.0 0.0 0.0 0.0 0.0 0.0</pose>

    <link name="base_footprint"/>

    <link name="base_link">

      <inertial>
        <pose>-0.064 0 0.1 0 0 0</pose>
        <inertia>
          <ixx>4.2111447e-02</ixx>
          <ixy>0</ixy>
          <ixz>0</ixz>
          <iyy>4.2111447e-02</iyy>
          <iyz>0</iyz>
          <izz>7.5254874e-02</izz>
        </inertia>
        <mass>1.3729096e+00</mass>
      </inertial>

      <collision name="base_collision">
        <pose>-0.064 0 0.1 0 0 0</pose>
        <geometry>
          <box>
            <size>0.53 0.53 0.183</size>
          </box>
        </geometry>
      </collision>

      <visual name="base_visual">
        <pose>-0.064 0 0 0 0 0</pose>
        <geometry>
          <mesh>
            <uri>model://turtlebot3_common/new/waffle_base.dae</uri>
            <!--scale>0.001 0.001 0.001</scale-->
          </mesh>
        </geometry>
      </visual>
    </link>

    <link name="imu_link">
      <sensor name="tb3_imu" type="imu">
        <always_on>true</always_on>
        <update_rate>200</update_rate>
        <topic>imu</topic>
        <imu>
          <angular_velocity>
            <x>
              <noise type="gaussian">
                <mean>0.0</mean>
                <stddev>2e-4</stddev>
              </noise>
            </x>
            <y>
              <noise type="gaussian">
                <mean>0.0</mean>
                <stddev>2e-4</stddev>
              </noise>
            </y>
            <z>
              <noise type="gaussian">
                <mean>0.0</mean>
                <stddev>2e-4</stddev>
              </noise>
            </z>
          </angular_velocity>
          <linear_acceleration>
            <x>
              <noise type="gaussian">
                <mean>0.0</mean>
                <stddev>1.7e-2</stddev>
              </noise>
            </x>
            <y>
              <noise type="gaussian">
                <mean>0.0</mean>
                <stddev>1.7e-2</stddev>
              </noise>
            </y>
            <z>
              <noise type="gaussian">
                <mean>0.0</mean>
                <stddev>1.7e-2</stddev>
              </noise>
            </z>
          </linear_acceleration>
        </imu>                                                                    
      </sensor>
    </link>

    <link name="base_scan">    
      <inertial>
        <pose>-0.052 0 0.211 0 0 0</pose>
        <inertia>
          <ixx>0.001</ixx>
          <ixy>0.000</ixy>
          <ixz>0.000</ixz>
          <iyy>0.001</iyy>
          <iyz>0.000</iyz>
          <izz>0.001</izz>
        </inertia>
        <mass>0.114</mass>
      </inertial>

      <collision name="lidar_sensor_collision">
        <pose>-0.052 0 0.211 0 0 0</pose>
        <geometry>
          <cylinder>
            <radius>0.0508</radius>
            <length>0.055</length>
          </cylinder>
        </geometry>
      </collision>

      <visual name="lidar_sensor_visual">
        <pose>-0.064 0 0.221 0 0 0</pose>
        <geometry>
          <mesh>
            <uri>model://turtlebot3_common/new/lds.dae</uri>
            <scale>0.1 0.1 0.1</scale>
          </mesh>
        </geometry>
      </visual>

      <sensor name="hls_lfcd_lds" type="gpu_lidar">
        <always_on>true</always_on>
        <visualize>true</visualize>
        <pose>-0.064 0 0.221 0 0 0</pose>
        <update_rate>5</update_rate>
        <topic>scan</topic>
        <gz_frame_id>base_scan</gz_frame_id>
        <lidar>
          <scan>
            <horizontal>
              <samples>360</samples>
              <resolution>1.000000</resolution>
              <min_angle>0.000000</min_angle>
              <max_angle>6.280000</max_angle>
            </horizontal>
          </scan>
          <range>
            <min>0.120000</min>
            <max>5.0</max>
            <resolution>0.015000</resolution>
          </range>
          <noise>
            <type>gaussian</type>
            <mean>0.0</mean>
            <stddev>0.01</stddev>
          </noise>
        </lidar>
      </sensor>
    </link>

    <link name="wheel_left_link">
      <inertial>
        <pose>0.0 0.28 0.023 1.57 0 0</pose>
        <mass>0.2</mass>
        <inertia>
          <ixx>0.00023821666666666672</ixx>
          <ixy>0.0</ixy>
          <ixz>0.0</ixz>
          <iyy>0.00023821666666666672</iyy>
          <iyz>0.0</iyz>
          <izz>0.00043560000000000007</izz>
        </inertia>
      </inertial>

      <collision name="wheel_left_collision">
        <pose>0.0 0.28 0.023 1.57 0 0</pose>
        <geometry>
          <cylinder>
            <radius>0.066</radius>
            <length>0.035</length>
          </cylinder>
        </geometry>
        <!--surface>
          <friction>
            <ode>
              <mu>100000.0</mu>
              <mu2>100000.0</mu2>
              <fdir1>0 0 0</fdir1>
              <slip1>0.0</slip1>
              <slip2>0.0</slip2>
            </ode>
          </friction>
          <contact>
            <ode>
              <soft_cfm>0</soft_cfm>
              <soft_erp>0.2</soft_erp>
              <kp>1e+5</kp>
              <kd>1</kd>
              <max_vel>0.01</max_vel>
              <min_depth>0.001</min_depth>
            </ode>
          </contact>
        </surface-->
      </collision>

      <visual name="wheel_left_visual">
        <pose>0.0 0.28 0.023 0 0 0</pose>
        <geometry>
          <mesh>
            <uri>model://turtlebot3_common/new/left-tire.dae</uri>
            <!--scale>0.001 0.001 0.001</scale-->
          </mesh>
        </geometry>
      </visual>
    </link>

    <link name="wheel_right_link">
      <inertial>
        <pose>0.0 -0.28 0.023 1.57 0 0</pose>
        <mass>0.2</mass>
        <inertia>
          <ixx>0.00023821666666666672</ixx>
          <ixy>0.0</ixy>
          <ixz>0.0</ixz>
          <iyy>0.00023821666666666672</iyy>
          <iyz>0.0</iyz>
          <izz>0.00043560000000000007</izz>
        </inertia>
      </inertial>
      <collision name="wheel_right_collision">
        <pose>0.0 -0.28 0.023 1.57 0 0</pose>
        <geometry>
          <cylinder>
            <radius>0.066</radius>
            <length>0.035</length>
          </cylinder>
        </geometry>
        <!--surface>
          <friction>
            <ode>
              <mu>100000.0</mu>
              <mu2>100000.0</mu2>
              <fdir1>0 0 0</fdir1>
              <slip1>0.0</slip1>
              <slip2>0.0</slip2>
            </ode>
          </friction>
          <contact>
            <ode>
              <soft_cfm>0</soft_cfm>
              <soft_erp>0.2</soft_erp>
              <kp>1e+5</kp>
              <kd>1</kd>
              <max_vel>0.01</max_vel>
              <min_depth>0.001</min_depth>
            </ode>
          </contact>
        </surface-->
      </collision>

      <visual name="wheel_right_visual">
        <pose>0.0 -0.28 0.023 0 0 3.141592654</pose>
        <geometry>
          <mesh>
            <uri>model://turtlebot3_common/new/left-tire.dae</uri>
            <!--scale>0.001 0.001 0.001</scale-->
          </mesh>
        </geometry>
      </visual>
    </link>

    <link name='caster_back_right_link'>
      <pose>-0.25 -0.18 -0.004 -1.57 0 0</pose>
      <inertial>
        <mass>1.0</mass>
        <inertia>
          <ixx>0.00036</ixx>
          <ixy>0.0</ixy>
          <ixz>0.0</ixz>
          <iyy>0.00036</iyy>
          <iyz>0.0</iyz>
          <izz>0.00036</izz>
        </inertia>
      </inertial>
      <visual name='caster_back_right_visual'>
        <geometry>
          <sphere>
           <radius>0.03</radius>
          </sphere>
        </geometry>
      </visual>
      <collision name='collision'>
        <geometry>
          <sphere>
            <radius>0.03000</radius>
          </sphere>
        </geometry>
        <!--surface>
          <contact>
            <ode>
              <soft_cfm>0</soft_cfm>
              <soft_erp>0.2</soft_erp>
              <kp>1e+5</kp>
              <kd>1</kd>
              <max_vel>0.01</max_vel>
              <min_depth>0.001</min_depth>
            </ode>
          </contact>
        </surface-->
      </collision>
    </link>

    <link name='caster_back_left_link'>
      <pose>-0.25 0.18 -0.004 -1.57 0 0</pose>
      <inertial>
        <mass>1.0</mass>
        <inertia>
          <ixx>0.00036</ixx>
          <ixy>0.0</ixy>
          <ixz>0.0</ixz>
          <iyy>0.00036</iyy>
          <iyz>0.0</iyz>
          <izz>0.00036</izz>
        </inertia>
      </inertial>
      <visual name='caster_back_left_visual'>
        <geometry>
          <sphere>
           <radius>0.03</radius>
          </sphere>
        </geometry>
      </visual>
      <collision name='collision'>
        <geometry>
          <sphere>
            <radius>0.03000</radius>
          </sphere>
        </geometry>
        <!--surface>
          <contact>
            <ode>
              <soft_cfm>0</soft_cfm>
              <soft_erp>0.2</soft_erp>
              <kp>1e+5</kp>
              <kd>1</kd>
              <max_vel>0.01</max_vel>
              <min_depth>0.001</min_depth>
            </ode>
          </contact>
        </surface-->
      </collision>
    </link>

    <link name="camera_link"/>

    <link name="camera_rgb_frame">
      <inertial>
        <pose>0.069 -0.047 0.107 0 0 0</pose>
        <inertia>
          <ixx>2.083333333333334e-05</ixx>
          <ixy>0.000</ixy>
          <ixz>0.000</ixz>
          <iyy>2.083333333333334e-05</iyy>
          <iyz>0.000</iyz>
          <izz>2.083333333333334e-05</izz>
        </inertia>
        <mass>0.05</mass>
      </inertial>

      <pose>0.069 -0.047 0.107 0 0 0</pose>
      <sensor name="camera" type="camera">
        <always_on>true</always_on>
        <visualize>true</visualize>
        <update_rate>30</update_rate>
        <topic>camera/image_raw</topic>
        <gz_frame_id>camera_rgb_frame</gz_frame_id>
        <camera name="intel_realsense_r200">
          <camera_info_topic>camera/camera_info</camera_info_topic>
          <horizontal_fov>1.02974</horizontal_fov>
          <image>
            <width>1920</width>
            <height>1080</height>
            <format>R8G8B8</format>
          </image>
          <clip>
            <near>0.02</near>
            <far>300</far>
          </clip>
          <noise>
            <type>gaussian</type>
            <!-- Noise is sampled independently per pixel on each frame.
                  That pixel's noise value is added to each of its color
                  channels, which at that point lie in the range [0,1]. -->
            <mean>0.0</mean>
            <stddev>0.007</stddev>
          </noise>
        </camera>
      </sensor>
    </link>    

    <joint name="base_joint" type="fixed">
      <parent>base_footprint</parent>
      <child>base_link</child>
      <pose>0.0 0.0 0.010 0 0 0</pose>
    </joint>

    <joint name="wheel_left_joint" type="revolute">
      <parent>base_link</parent>
      <child>wheel_left_link</child>
      <pose>0.0 0.144 0.023 -1.57 0 0</pose>
      <axis>
        <xyz>0 0 1</xyz>
        <effort>20</effort>
      </axis>
    </joint>

    <joint name="wheel_right_joint" type="revolute">
      <parent>base_link</parent>
      <child>wheel_right_link</child>
      <pose>0.0 -0.144 0.023 -1.57 0 0</pose>
      <axis>
        <xyz>0 0 1</xyz>
        <effort>20</effort>
      </axis>
    </joint>

    <joint name='caster_back_right_joint' type='ball'>
      <parent>base_link</parent>
      <child>caster_back_right_link</child>
    </joint>

    <joint name='caster_back_left_joint' type='ball'>
      <parent>base_link</parent>
      <child>caster_back_left_link</child>
    </joint>

    <joint name="imu_joint" type="fixed">
      <parent>base_link</parent>
      <child>imu_link</child>
      <pose>-0.032 0 0.068 0 0 0</pose>
      <axis>
        <xyz>0 0 1</xyz>
      </axis>
    </joint>    

    <joint name="lidar_joint" type="fixed">
      <parent>base_link</parent>
      <child>base_scan</child>
      <pose>-0.064 0 0.121 0 0 0</pose>
      <axis>
        <xyz>0 0 1</xyz>
      </axis>
    </joint>

    <joint name="camera_joint" type="fixed">
      <parent>base_link</parent>
      <child>camera_link</child>
      <pose>0.064 -0.065 0.094 0 0 0</pose>
      <axis>
        <xyz>0 0 1</xyz>
      </axis>
    </joint>

    <joint name="camera_rgb_joint" type="fixed">
      <parent>camera_link</parent>
      <child>camera_rgb_frame</child>
      <pose>0.005 0.018 0.013 0 0 0</pose>
      <axis>
        <xyz>0 0 1</xyz>
      </axis>
    </joint>

    <plugin filename="gz-sim-diff-drive-system" name="gz::sim::systems::DiffDrive">
      <!-- wheels -->
      <left_joint>wheel_left_joint</left_joint>
      <right_joint>wheel_right_joint</right_joint>

      <!-- kinematics -->
      <wheel_separation>0.56</wheel_separation>
      <wheel_radius>0.066</wheel_radius> <!-- computed from <wheel_diameter> in the original plugin-->

      <topic>/cmd_vel</topic> <!-- from <commant_topic> -->

      <odom_topic>/odom</odom_topic> <!-- from <odometry_topic> -->
      <frame_id>odom</frame_id> <!-- from <odometry_frame> -->
      <child_frame_id>base_link</child_frame_id> <!-- from <robot_base_frame> -->
      <odom_publisher_frequency>10</odom_publisher_frequency> <!-- from <update_rate>-->

      <tf_topic>/tf</tf_topic> <!-- Short topic name for tf output -->
    </plugin>

    <plugin filename="gz-sim-joint-state-publisher-system"
        name="gz::sim::systems::JointStatePublisher">
      <topic>joint_states</topic> 
      <joint_name>wheel_left_joint</joint_name>
      <joint_name>wheel_right_joint</joint_name>
    </plugin>

  </model>
</sdf>
